Workbook

Sheet Cleaned Dataset
A1: OrderID | B1: Date | C1: CustomerID | D1: Product | E1: Quantity | F1: UnitPrice | G1: ShippingAddress | H1: PaymentMethod | I1: OrderStatus | J1: TrackingNumber | K1: ItemsInCart | L1: CouponCode | M1: ReferralSource | N1: TotalPrice | O1: Month | P1: Returning Customer
A2: ORD200000 | B2: 44930 | C2: C72649 | D2: Monitor | E2: 5 | F2: 570.62 | G2: 928 Main St | H2: Debit Card | I2: Shipped | J2: TRK37947903 | K2: 7 | L2: SAVE10 | M2: Instagram | N2: 2853.1 | O2: =TEXT(B2,"mmmm") -> January | P2: {=IF(COUNTIF('Cleaned Dataset'!$C$2:$C$1201,C2)>1,"Yes","No")} -> No
A3: ORD200001 | B3: 45527 | C3: C75739 | D3: Phone | E3: 2 | F3: 151.35 | G3: 823 Main St | H3: Online | I3: Shipped | J3: TRK91186779 | K3: 3 | L3: SAVE10 | M3: Referral | N3: 302.7 | O3: =TEXT(B3,"mmmm") -> August | P3: {=IF(COUNTIF('Cleaned Dataset'!$C$2:$C$1201,C3)>1,"Yes","No")} -> No
A4: ORD200002 | B4: 45349 | C4: C81728 | D4: Tablet | E4: 5 | F4: 550.68 | G4: 512 Main St | H4: Credit Card | I4: Cancelled | J4: TRK42903982 | K4: 8 | L4: FREESHIP | M4: Email | N4: 2753.4 | O4: =TEXT(B4,"mmmm") -> February | P4: {=IF(COUNTIF('Cleaned Dataset'!$C$2:$C$1201,C4)>1,"Yes","No")} -> No
A5: ORD200003 | B5: 45214 | C5: C33540 | D5: Chair | E5: 1 | F5: 273.19 | G5: 275 Main St | H5: Debit Card | I5: Returned | J5: TRK62788070 | K5: 5 | L5: SAVE10 | M5: Facebook | N5: 273.19 | O5: =TEXT(B5,"mmmm") -> October | P5: {=IF(COUNTIF('Cleaned Dataset'!$C$2:$C$1201,C5)>1,"Yes","No")} -> No
A6: ORD200004 | B6: 45785 | C6: C81840 | D6: Printer | E6: 4 | F6: 626.01 | G6: 668 Main St | H6: Online | I6: Delivered | J6: TRK29241424 | K6: 8 | L6: SAVE10 | M6: Email | N6: 2504.04 | O6: =TEXT(B6,"mmmm") -> May | P6: {=IF(COUNTIF('Cleaned Dataset'!$C$2:$C$1201,C6)>1,"Yes","No")} -> No
A7: ORD200005 | B7: 45222 | C7: C37249 | D7: Phone | E7: 2 | F7: 245.86 | G7: 934 Main St | H7: Credit Card | I7: Shipped | J7: TRK72976927 | K7: 4 | L7: SAVE10 | M7: Instagram | N7: 491.72 | O7: =TEXT(B7,"mmmm") -> October | P7: {=IF(COUNTIF('Cleaned Dataset'!$C$2:$C$1201,C7)>1,"Yes","No")} -> No
A8: ORD200006 | B8: 45825 | C8: C83492 | D8: Laptop | E8: 1 | F8: 664.42 | G8: 986 Main St | H8: Gift Card | I8: Returned | J8: TRK96417362 | K8: 6 | L8: SAVE10 | M8: Facebook | N8: 664.42 | O8: =TEXT(B8,"mmmm") -> June | P8: {=IF(COUNTIF('Cleaned Dataset'!$C$2:$C$1201,C8)>1,"Yes","No")} -> No
A9: ORD200007 | B9: 45058 | C9: C41460 | D9: Monitor | E9: 5 | F9: 149.55 | G9: 706 Main St | H9: Cash | I9: Shipped | J9: TRK78809193 | K9: 9 | L9: FREESHIP | M9: Facebook | N9: 747.75 | O9: =TEXT(B9,"mmmm") -> May | P9: {=IF(COUNTIF('Cleaned Dataset'!$C$2:$C$1201,C9)>1,"Yes","No")} -> No
A10: ORD200008 | B10: 45749 | C10: C26817 | D10: Phone | E10: 2 | F10: 134.28 | G10: 904 Main St | H10: Gift Card | I10: Cancelled | J10: TRK61042692 | K10: 2 | L10: No data | M10: Email | N10: 268.56 | O10: =TEXT(B10,"mmmm") -> April | P10: {=IF(COUNTIF('Cleaned Dataset'!$C$2:$C$1201,C10)>1,"Yes","No")} -> No
A11: ORD200009 | B11: 45251 | C11: C31946 | D11: Desk | E11: 4 | F11: 509.38 | G11: 102 Main St | H11: Credit Card | I11: Shipped | J11: TRK33478363 | K11: 6 | L11: SAVE10 | M11: Google | N11: 2037.52 | O11: =TEXT(B11,"mmmm") -> November | P11: {=IF(COUNTIF('Cleaned Dataset'!$C$2:$C$1201,C11)>1,"Yes","No")} -> No
A12: ORD200010 | B12: 45289 | C12: C43443 | D12: Tablet | E12: 5 | F12: 625.97 | G12: 333 Main St | H12: Credit Card | I12: Returned | J12: TRK98859248 | K12: 9 | L12: WINTER15 | M12: Instagram | N12: 3129.85 | O12: =TEXT(B12,"mmmm") -> December | P12: {=IF(COUNTIF('Cleaned Dataset'!$C$2:$C$1201,C12)>1,"Yes","No")} -> No
A13: ORD200011 | B13: 45339 | C13: C93861 | D13: Monitor | E13: 3 | F13: 49.14 | G13: 831 Main St | H13: Online | I13: Returned | J13: TRK48234646 | K13: 7 | L13: SAVE10 | M13: Email | N13: 147.42 | O13: =TEXT(B13,"mmmm") -> February | P13: {=IF(COUNTIF('Cleaned Dataset'!$C$2:$C$1201,C13)>1,"Yes","No")} -> No
... A1201: ORD201199 | B1201: 45088 | C1201: C57502 | D1201: Tablet | E1201: 4 | F1201: 560.58 | G1201: 201 Main St | H1201: Gift Card | I1201: Returned | J1201: TRK51116746 | K1201: 6 | L1201: SAVE10 | M1201: Referral | N1201: 2242.32 | O1201: =TEXT(B1201,"mmmm") -> June | P1201: {=IF(COUNTIF('Cleaned Dataset'!$C$2:$C$1201,C1201)>1,"Yes","No")} -> No

Sheet EDA Analysis
A1: EDA ANALYSIS — DecodeLabs Internship Project 2
A2: Metric | B2: Value
A3: 🧾 Order Summary
A4: Total Orders | B4: =COUNTA('Cleaned Dataset'!A:A)-1 -> 1200
A5: Average Order Price | B5: =AVERAGE('Cleaned Dataset'!N:N) -> 1053.9683
A6: Median Order Price | B6: =MEDIAN('Cleaned Dataset'!N:N) -> 823.615
A7: Highest Order Price | B7: =MAX('Cleaned Dataset'!N:N) -> 3456.4
A8: Lowest Order Price | B8: =MIN('Cleaned Dataset'!N:N) -> 11.39
A9: 📦 Product Performance
A10: Most Sold Product | B10: {=INDEX('Cleaned Dataset'!D:D,MATCH(MAX(COUNTIF('Cleaned Dataset'!D2:D1201,'Cleaned Dataset'!D2:D1201)),COUNTIF('Cleaned Dataset'!D2:D1201,'Cleaned Dataset'!D2:D1201),0)+1)} -> Printer
A11: Most Returned Product | B11: {=INDEX('Cleaned Dataset'!D:D,MATCH(MAX(COUNTIFS('Cleaned Dataset'!D2:D1201,'Cleaned Dataset'!D2:D1201,'Cleaned Dataset'!I2:I1201,"Returned")),COUNTIFS('Cleaned Dataset'!D2:D1201,'Cleaned Dataset'!D2:D1201,'Cleaned Dataset'!I2:I1201,"Returned"),0)+1)} -> Tablet
A12: Most Shipped Product | B12: {=INDEX('Cleaned Dataset'!D:D,MATCH(MAX(COUNTIFS('Cleaned Dataset'!D2:D1201,'Cleaned Dataset'!D2:D1201,'Cleaned Dataset'!I2:I1201,"Shipped")),COUNTIFS('Cleaned Dataset'!D2:D1201,'Cleaned Dataset'!D2:D1201,'Cleaned Dataset'!I2:I1201,"Shipped"),0)+1)} -> Printer
A13: 🚦 Order Status Breakdown
A14: Total Shipped Orders | B14: =COUNTIF('Cleaned Dataset'!I:I,"Shipped") -> 235
A15: Total Delivered Orders | B15: =COUNTIF('Cleaned Dataset'!I:I,"Delivered") -> 231
A16: Total Cancelled Orders | B16: =COUNTIF('Cleaned Dataset'!I:I,"Cancelled") -> 250
A17: Total Returned Orders | B17: =COUNTIF('Cleaned Dataset'!I:I,"Returned") -> 247
A18: Total Pending Orders | B18: =COUNTIF('Cleaned Dataset'!I:I,"Pending") -> 237
A19: 💳 Payment Analysis
A20: Most Used Payment Method | B20: {=INDEX('Cleaned Dataset'!H:H,MATCH(MAX(COUNTIF('Cleaned Dataset'!H2:H1201,'Cleaned Dataset'!H2:H1201)),COUNTIF('Cleaned Dataset'!H2:H1201,'Cleaned Dataset'!H2:H1201),0)+1)} -> Online
A21: 📣 Referral Source Analysis
A22: Most Popular Referral Source | B22: {=INDEX('Cleaned Dataset'!M:M,MATCH(MAX(COUNTIF('Cleaned Dataset'!M2:M1201,'Cleaned Dataset'!M2:M1201)),COUNTIF('Cleaned Dataset'!M2:M1201,'Cleaned Dataset'!M2:M1201),0)+1)} -> Instagram
A23: Source With Highest Income | B23: {=INDEX('Cleaned Dataset'!M:M,MATCH(MAX(SUMIF('Cleaned Dataset'!M2:M1201,'Cleaned Dataset'!M2:M1201,'Cleaned Dataset'!N2:N1201)),SUMIF('Cleaned Dataset'!M2:M1201,'Cleaned Dataset'!M2:M1201,'Cleaned Dataset'!N2:N1201),0)+1)} -> Instagram
A24: Source With Most Cancellations | B24: {=INDEX('Cleaned Dataset'!M:M,MATCH(MAX(COUNTIFS('Cleaned Dataset'!M2:M1201,'Cleaned Dataset'!M2:M1201,'Cleaned Dataset'!I2:I1201,"Cancelled")),COUNTIFS('Cleaned Dataset'!M2:M1201,'Cleaned Dataset'!M2:M1201,'Cleaned Dataset'!I2:I1201,"Cancelled"),0)+1)} -> Email
A25: Source With Most Coupon Users | B25: {=INDEX('Cleaned Dataset'!M:M,MATCH(MAX(COUNTIFS('Cleaned Dataset'!M2:M1201,'Cleaned Dataset'!M2:M1201,'Cleaned Dataset'!L2:L1201,"<>")),COUNTIFS('Cleaned Dataset'!M2:M1201,'Cleaned Dataset'!M2:M1201,'Cleaned Dataset'!L2:L1201,"<>"),0)+1)} -> Instagram
A26: 🎟️ Coupon Analysis
A27: Coupon Users Count | B27: =COUNTIF('Cleaned Dataset'!L:L,"<>")- COUNTIF('Cleaned Dataset'!L:L,"No data")-1 -> 891
A28: Non Coupon Users Count | B28: =COUNTIF('Cleaned Dataset'!L:L,"No data") -> 309
A29: 📅 Time Analysis
A30: Day of Week With Most Orders | B30: {=TEXT(INDEX('Cleaned Dataset'!B:B,MATCH(MAX(COUNTIF('Cleaned Dataset'!B2:B1201,'Cleaned Dataset'!B2:B1201)),COUNTIF('Cleaned Dataset'!B2:B1201,'Cleaned Dataset'!B2:B1201),0)+1),"dddd")} -> Sunday
A31: Month With Most Orders | B31: {=INDEX('Cleaned Dataset'!O2:O1201,MATCH(MAX(COUNTIF('Cleaned Dataset'!O2:O1201,'Cleaned Dataset'!O2:O1201)),COUNTIF('Cleaned Dataset'!O2:O1201,'Cleaned Dataset'!O2:O1201),0))} -> June
A32: Month With Least Orders | B32: {=INDEX('Cleaned Dataset'!O2:O1201,MATCH(MIN(COUNTIF('Cleaned Dataset'!O2:O1201,'Cleaned Dataset'!O2:O1201)),COUNTIF('Cleaned Dataset'!O2:O1201,'Cleaned Dataset'!O2:O1201),0))} -> September
A33: 🛒 Cart Behavior
A34: Avg Items in Cart - Shipped | B34: =ROUND(AVERAGEIF('Cleaned Dataset'!I:I,"Shipped",'Cleaned Dataset'!K:K),0) -> 5
A35: Avg Items in Cart - Cancelled | B35: =ROUND(AVERAGEIF('Cleaned Dataset'!I:I,"Cancelled",'Cleaned Dataset'!K:K),0) -> 6
A36: Avg Items in Cart - Returned | B36: {=ROUND(AVERAGEIF('Cleaned Dataset'!I:I,"Returned",'Cleaned Dataset'!K:K),0)} -> 5
A37: Customer Retention
A38: Returning Customers | B38: {=SUMPRODUCT((COUNTIF('Cleaned Dataset'!C2:C1201,'Cleaned Dataset'!C2:C1201)>1)/COUNTIF('Cleaned Dataset'!C2:C1201,'Cleaned Dataset'!C2:C1201))} -> 11
A39: Max Orders by one customer | B39: =ROUND(AVERAGEIF('Cleaned Dataset'!I:I,"Cancelled",'Cleaned Dataset'!K:K),0) -> 6
A40: Most Bought Products by Returning Customers | B40: {=INDEX('Cleaned Dataset'!D2:D1201,MATCH(MAX(COUNTIFS('Cleaned Dataset'!P2:P1201,"Yes",'Cleaned Dataset'!D2:D1201,'Cleaned Dataset'!D2:D1201)),COUNTIFS('Cleaned Dataset'!P2:P1201,"Yes",'Cleaned Dataset'!D2:D1201,'Cleaned Dataset'!D2:D1201),0))} -> Tablet
...
